Выполнится ли .catch? Поясните свой ответ.

new Promise(function(resolve, reject) {
  setTimeout(() => {
    throw new Error("Whoops!");
  }, 1000);
}).catch(alert);

Исключение лежит в макрозадаче, она исполнится только после завершения остального кода.
К этому моменту catch уже "закончился".